Workbook

Sheet 현대로템
A1: 현대로템
A2: 45777
G4: (단위: 백만) | I4: *NOTE
B5: 주가 | C5: 유통주식수 | D5: 시가총액 | E5: ibd | F5: ltm ebit | G5: tax rate | I5: 분기보고서 내 주식의 총수 기재하지 않아 직전 사업보고서 사용
B6: 105000 | C6: =D24 -> 109142 | D6: =(B6*C6)/10^6 -> 11459.91 | E6: =SUMIF(A:A,E5,C:C)/10^3 -> 252879.68 | F6: =(H41+N41-J41)/1000 -> 614734.59 | G6: 0.264
B9: 4. 주식의 총수 등
B11: 가. 주식의 총수 현황
B12: (기준일 : | C12: 2024.12.31 | D12: ) | E12: (단위 : 천주, %)
B13: 구 분 | D13: 주식의 종류 | G13: 비고
D14: 보통주 | E14: 우선주 | F14: 합계
B15: Ⅰ. 발행할 주식의 총수 | D15: 200000 | E15: - | F15: 200000 | G15: 정관상 발행 가능한 주식 총수 : 2억주 (보통주/우선주 구분없음)
B16: Ⅱ. 현재까지 발행한 주식의 총수 | D16: 115742 | E16: - | F16: 115742 | G16: -
B17: Ⅲ. 현재까지 감소한 주식의 총수 | D17: 6600 | E17: - | F17: 6600 | G17: -
C18: 1. 감자 | D18: 6600 | E18: - | F18: 6600 | G18: -
C19: 2. 이익소각 | D19: - | E19: - | F19: - | G19: -
C20: 3. 상환주식의 상환 | D20: - | E20: - | F20: - | G20: -
C21: 4. 기타 | D21: - | E21: - | F21: - | G21: -
B22: Ⅳ. 발행주식의 총수 (Ⅱ-Ⅲ) | D22: 109142 | E22: - | F22: 109142 | G22: -
B23: Ⅴ. 자기주식수 | D23: - | E23: - | F23: - | G23: -
B24: Ⅵ. 유통주식수 (Ⅳ-Ⅴ) | D24: 109142 | E24: - | F24: 109142 | G24: -
B25: Ⅶ. 자기주식 보유비율 | D25: - | E25: - | F25: - | G25: -
B30: 2-1. 연결 재무상태표 | G30: 2-2. 연결 포괄손익계산서 | M30: 2-2. 연결 포괄손익계산서
B31: 연결 재무상태표 | G31: 연결 포괄손익계산서 | M31: 연결 포괄손익계산서
B32: 제 27 기 1분기말 2025.03.31 현재 | G32: 제 27 기 1분기 2025.01.01 부터 2025.03.31 까지 | M32: 제 26 기 2024.01.01 부터 2024.12.31 까지
B33: 제 26 기말 2024.12.31 현재 | G33: 제 26 기 1분기 2024.01.01 부터 2024.03.31 까지 | M33: 제 25 기 2023.01.01 부터 2023.12.31 까지
B34: (단위 : 천원) | G34: (단위 : 천원) | M34: 제 24 기 2022.01.01 부터 2022.12.31 까지
C35: 제 27 기 1분기말 | D35: 제 26 기말 | H35: 제 27 기 1분기 | J35: 제 26 기 1분기 | M35: (단위 : 천원)
B36: 자산 | H36: 3개월 | I36: 누적 | J36: 3개월 | K36: 누적 | N36: 제 26 기 | O36: 제 25 기 | P36: 제 24 기
B37: 유동자산 | C37: 3679870454 | D37: 3686316730 | G37: 매출액 (주26,27,36,38) | H37: 1176141098 | I37: 1176141098 | J37: 747779451 | K37: 747779451 | M37: 매출액 (주26,27,36,38) | N37: 4376597857 | O37: 3587382453 | P37: 3163343615
B38: 현금및현금성자산 (주4,21,35) | C38: 491247668 | D38: 472258339 | G38: 매출원가 (주31,36) | H38: 889997959 | I38: 889997959 | J38: 643123856 | K38: 643123856 | M38: 매출원가 (주31,36) | N38: 3547550219 | O38: 3122984003 | P38: 2797911962
B39: 유동매출채권 (주5,21,27,35,36) | C39: 724917369 | D39: 909369742 | G39: 매출총이익 | H39: 286143139 | I39: 286143139 | J39: 104655595 | K39: 104655595 | M39: 매출총이익 | N39: 829047638 | O39: 464398450 | P39: 365431653
B40: 기타유동채권 (주6,21,36) | C40: 61559596 | D40: 55767350 | G40: 판매비와관리비 (주28,31,36) | H40: 83290471 | I40: 83290471 | J40: 59971982 | K40: 59971982 | M40: 판매비와관리비 (주28,31,36) | N40: 372482104 | O40: 254351856 | P40: 217944984
B41: 계약자산 (주5,27,36) | C41: 805573731 | D41: 802137829 | G41: 영업손익 (주38) | H41: 202852668 | I41: 202852668 | J41: 44683613 | K41: 44683613 | M41: 영업손익 (주38) | N41: 456565534 | O41: 210046594 | P41: 147486669
B42: 기타금융자산 (주4,7,21,35,36) | C42: 294935032 | D42: 298218173 | G42: 기타수익 (주21,29) | H42: 9355776 | I42: 9355776 | J42: 16489906 | K42: 16489906 | M42: 기타수익 (주21,29) | N42: 114050169 | O42: 82308356 | P42: 99193218
B43: 재고자산 (주8) | C43: 414002821 | D43: 315635860 | G43: 기타비용 (주21,29,31) | H43: 21700992 | I43: 21700992 | J43: 13866557 | K43: 13866557 | M43: 기타비용 (주21,29,31) | N43: 84254421 | O43: 111691312 | P43: 94560825
B44: 당기법인세자산 | C44: 1243180 | D44: 1104397 | G44: 금융수익 (주21,30,36) | H44: 23305785 | I44: 23305785 | J44: 25614528 | K44: 25614528 | M44: 금융수익 (주21,30,36) | N44: 75210934 | O44: 47601139 | P44: 28547869
B45: 기타유동자산 (주9,21,36) | C45: 886391057 | D45: 831825040 | G45: 금융비용 (주21,30) | H45: 11159778 | I45: 11159778 | J45: 18576411 | K45: 18576411 | M45: 금융비용 (주21,30) | N45: 51904505 | O45: 47230751 | P45: 76639752
B46: 비유동자산 | C46: 1564572067 | D46: 1599078010 | G46: 지분법이익(손실) (주15) | H46: -21018 | I46: -21018 | J46: -12317 | K46: -12317 | M46: 지분법이익(손실) (주15) | N46: -106623 | O46: -193203 | P46: -146542
B47: 비유동매출채권 (주5,21,27,35,36) | C47: 25591121 | D47: 59228280 | G47: 법인세비용차감전순이익(손실) | H47: 202632441 | I47: 202632441 | J47: 54332762 | K47: 54332762 | M47: 법인세비용차감전순이익(손실) | N47: 509561088 | O47: 180840823 | P47: 103880637
B48: 장기기타채권 (주4,6,21,35,36) | C48: 16571515 | D48: 16643090 | G48: 법인세비용(수익) (주32) | H48: 45486441 | I48: 45486441 | J48: -1299913 | K48: -1299913 | M48: 법인세비용(수익) (주32) | N48: 104301674 | O48: 24061845 | P48: -90653616
...

Sheet wacc
B4: 기업명 | C4: Debt to Capital | D4: Equity to Capital | E4: Market Value of Total Equity | F4: IBD | G4: Capital | H4: LTM EBIT | I4: Tax Rate | J4: Leveraged Equity Beta | K4: Unleveraged Equity Beta | M4: D/E
B5: ='한국한공우주'!A1 -> 한국항공우주 | C5: =F5/G5 -> 0.14488969 | D5: =E5/G5 -> 0.85511031 | E5: ='한국한공우주'!D6 -> 7310633 | F5: ='한국한공우주'!E6 -> 1238712 | G5: =E5+F5 -> 8549345 | H5: ='한국한공우주'!F6 -> 239519.23 | I5: ='한국한공우주'!G6 -> 0.231 | M5: =C5/D5 -> 0.16943977
B6: ='두산에너빌리티'!A1 -> 두산에너빌리티 | C6: =F6/G6 -> 0.2579385 | D6: =E6/G6 -> 0.7420615 | E6: ='두산에너빌리티'!D6 -> 18541467 | F6: ='두산에너빌리티'!E6 -> 6444962 | G6: =E6+F6 -> 24986429 | H6: ='두산에너빌리티'!F6 -> 802004 | I6: ='두산에너빌리티'!G6 -> 0.264 | M6: =C6/D6 -> 0.34759721
B7: ='한화시스템'!A1 -> 한화시스템 | C7: =F7/G7 -> 0.10079273 | D7: =E7/G7 -> 0.89920727 | E7: ='한화시스템'!D6 -> 6002483.7 | F7: ='한화시스템'!E6 -> 672822.29 | G7: =E7+F7 -> 6675306 | H7: ='한화시스템'!F6 -> 232034.59 | I7: ='한화시스템'!G6 -> 0.231 | M7: =C7/D7 -> 0.11209065
B8: ='LIG넥스원'!A1 -> LIG디펜스앤에어로스페이스 | C8: =F8/G8 -> 0.051813125 | D8: =E8/G8 -> 0.94818687 | E8: ='LIG넥스원'!D6 -> 5405001.3 | F8: ='LIG넥스원'!E6 -> 295353.18 | G8: =E8+F8 -> 5700354.5 | H8: ='LIG넥스원'!F6 -> 276386.04 | I8: ='LIG넥스원'!G6 -> 0.231 | M8: =C8/D8 -> 0.054644424
B11: avg | C11: =AVERAGE(C5:C8) -> 0.13885851 | D11: =AVERAGE(D5:D8) -> 0.86114149 | M11: =AVERAGE(M5:M8) -> 0.17094301
B12: med | C12: =AVERAGE(C6:C9) -> 0.13684812 | D12: =AVERAGE(D6:D9) -> 0.86315188 | M12: =AVERAGE(M6:M9) -> 0.17144409

Sheet peer >>

Sheet 한국한공우주
A1: 한국항공우주
A2: 45777
G4: (단위: 백만)
B5: 주가 | C5: 유통주식수 | D5: 시가총액 | E5: ibd | F5: ltm ebit | G5: tax rate
B6: 75000 | C6: =D22 -> 97475107 | D6: =(B6*C6)/10^6 -> 7310633 | E6: =SUMIF(A:A,E5,C:C)/10^6+(D94+D102)/10^3 -> 1238712 | F6: =(H39+N39-J39)/10^6 -> 239519.23 | G6: =IF(F6<=200, 0.99, IF(F6<=20000, 0.209, IF(F6<=300000, 0.231, 0.264))) -> 0.231
B9: 4. 주식의 총수 등
B12: (기준일 : | C12: 45747 | D12: ) | E12: (단위 : 주, %)
B13: 구 분 | D13: 주식의 종류 | G13: 비고
D14: 보통주 | E14: 우선주 | F14: 합계
B15: Ⅰ. 발행할 주식의 총수 | D15: 200000000 | E15: - | F15: 200000000 | G15: -
B16: Ⅱ. 현재까지 발행한 주식의 총수 | D16: 148907209 | E16: - | F16: 148907209 | G16: -
B17: Ⅲ. 현재까지 감소한 주식의 총수 | D17: 51432102 | E17: - | F17: 51432102 | G17: -
C18: 1. 감자 | D18: 51432102 | E18: - | F18: 51432102 | G18: -
C19: 2. 이익소각 | D19: - | E19: - | F19: - | G19: -
C20: 3. 상환주식의 상환 | D20: - | E20: - | F20: - | G20: -
C21: 4. 기타 | D21: - | E21: - | F21: - | G21: -
B22: Ⅳ. 발행주식의 총수 (Ⅱ-Ⅲ) | D22: 97475107 | E22: - | F22: 97475107 | G22: -
B23: Ⅴ. 자기주식수 | D23: - | E23: - | F23: - | G23: -
B24: Ⅵ. 유통주식수 (Ⅳ-Ⅴ) | D24: 97475107 | E24: - | F24: 97475107 | G24: -
B25: Ⅶ. 자기주식 보유비율 | D25: - | E25: - | F25: - | G25: -
B28: 2-1. 연결 재무상태표 | G28: 2-2. 연결 포괄손익계산서 | M28: 2-2. 연결 포괄손익계산서
B29: 연결 재무상태표 | G29: 연결 포괄손익계산서 | M29: 연결 포괄손익계산서
B30: 제 27 기 1분기말 2025.03.31 현재 | G30: 제 27 기 1분기 2025.01.01 부터 2025.03.31 까지 | M30: 제 26 기 2024.01.01 부터 2024.12.31 까지
B31: 제 26 기말 2024.12.31 현재 | G31: 제 26 기 1분기 2024.01.01 부터 2024.03.31 까지 | M31: 제 25 기 2023.01.01 부터 2023.12.31 까지
B32: (단위 : 원) | G32: (단위 : 원) | M32: 제 24 기 2022.01.01 부터 2022.12.31 까지
C33: 제 27 기 1분기말 | D33: 제 26 기말 | H33: 제 27 기 1분기 | J33: 제 26 기 1분기 | M33: (단위 : 원)
B34: 자산 | H34: 3개월 | I34: 누적 | J34: 3개월 | K34: 누적 | N34: 제 26 기 | O34: 제 25 기 | P34: 제 24 기
B35: 유동자산 | C35: 6133242748971 | D35: 5439008063568 | G35: 수익(매출액) (주26,33,36,37) | H35: 699256592260 | I35: 699256592260 | J35: 739922390124 | K35: 739922390124 | M35: 수익(매출액) (주26,33,36,37) | N35: 3633742105840 | O35: 3819344382446 | P35: 2786888282702
B36: 현금및현금성자산 (주6,35) | C36: 138032136378 | D36: 114716160403 | G36: 매출원가 (주27,33) | H36: 578930842958 | I36: 578930842958 | J36: 642207439792 | K36: 642207439792 | M36: 매출원가 (주27,33) | N36: 3152251662461 | O36: 3355494014353 | P36: 2413060986583
B37: 유동당기손익-공정가치 측정 금융상품 (주5,6,9,35) | C37: 300000000000 | D37: 27131621918 | G37: 매출총이익 | H37: 120325749302 | I37: 120325749302 | J37: 97714950332 | K37: 97714950332 | M37: 매출총이익 | N37: 481490443379 | O37: 463850368093 | P37: 373827296119
B38: 유동매출채권 (주6,7,26,33) | C38: 395719299735 | D38: 398755279903 | G38: 판매비와관리비 (주27,28) | H38: 73512834257 | I38: 73512834257 | J38: 49702958969 | K38: 49702958969 | M38: 판매비와관리비 (주27,28) | N38: 240772132979 | O38: 216339884938 | P38: 232209628801
B39: 유동계약자산 (주7,26) | C39: 620054283361 | D39: 481616109522 | G39: 영업이익(손실) (주36) | H39: 46812915045 | I39: 46812915045 | J39: 48011991363 | K39: 48011991363 | M39: 영업이익(손실) (주36) | N39: 240718310400 | O39: 247510483155 | P39: 141617667318
B40: 기타유동금융자산 (주6,7,33) | C40: 21653458791 | D40: 22371366814 | G40: 기타이익 (주29) | H40: 438466476 | I40: 438466476 | J40: 503545853 | K40: 503545853 | M40: 기타이익 (주29,33) | N40: 8943702027 | O40: 16901628950 | P40: 10690416573
B41: 유동재고자산 (주8) | C41: 2718905396687 | D41: 2359034707814 | G41: 기타손실 (주29) | H41: 581091315 | I41: 581091315 | J41: 694839418 | K41: 694839418 | M41: 기타손실 (주29,33) | N41: 27300056509 | O41: 20906948393 | P41: 6871167952
B42: 당기법인세자산 (주31) | C42: 62362000 | D42: 53939720 | G42: 금융수익 (주6,30,33) | H42: 55198453540 | I42: 55198453540 | J42: 43618761478 | K42: 43618761478 | M42: 금융수익 (주6,30,33) | N42: 121109213680 | O42: 112453943443 | P42: 109675065480
B43: 기타유동자산 (주14,33) | C43: 1938815812019 | D43: 2035328877474 | G43: 금융원가 (주6,30) | H43: 65183983326 | I43: 65183983326 | J43: 45064043382 | K43: 45064043382 | M43: 금융원가 (주6,30) | N43: 143909460657 | O43: 87591601007 | P43: 132310966928
B44: 비유동자산 | C44: 2600123288969 | D44: 2586530345825 | G44: 지분법손실 (주10) | H44: 976509784 | I44: 976509784 | J44: 946863349 | K44: 946863349 | M44: 지분법이익 (주10) | O44: 1369167843 | P44: 1334591136
B45: 비유동당기손익-공정가치 측정 금융상품 (주5,6,9) | C45: 79626906529 | D45: 79655609179 | G45: 법인세차감전순이익 | H45: 35708250636 | I45: 35708250636 | J45: 45428552545 | K45: 45428552545 | M45: 지분법손실 (주10) | N45: 2455312616 | O45: 1020953512 | P45: 2013675671
B46: 비유동매출채권 (주6,7,26) | C46: 29580273545 | D46: 29511304701 | G46: 법인세비용 (주31) | H46: 6544179205 | I46: 6544179205 | J46: 10202220761 | K46: 10202220761 | M46: 법인세차감전순이익 | N46: 197106396325 | O46: 268715720479 | P46: 122121929956
B47: 기타비유동금융자산 (주4,6,7,33) | C47: 8281520193 | D47: 9200977948 | G47: 당기순이익 | H47: 29164071431 | I47: 29164071431 | J47: 35226331784 | K47: 35226331784 | M47: 법인세비용 (주31) | N47: 26210985348 | O47: 47314600584 | P47: 6202534236
...

Sheet 두산에너빌리티
A1: 두산에너빌리티
A2: 45777
G4: (단위: 백만) | I4: *NOTE
B5: 주가 | C5: 유통주식수 | D5: 시가총액 | E5: ibd | F5: ltm ebit | G5: tax rate | I5: 분기보고서 내 주식의 총수 기재하지 않아 직전 사업보고서 사용
B6: 28950 | C6: =D32 -> 640465168 | D6: =(B6*C6)/10^6 -> 18541467 | E6: =SUMIF(A:A,E5,C:C) -> 6444962 | F6: =(H58+N58-J58) -> 802004 | G6: =IF(F6<=200, 0.99, IF(F6<=20000, 0.209, IF(F6<=300000, 0.231, 0.264))) -> 0.264
B9: 4. 주식의 총수 등
B11: 가. 주식의 총수 현황
B12: 당사의 정관에 의해 발행할 주식의 총수는 2,000,000,000주입니다.
B13: 당기말까지 당사가 발행한 주식의 총수는 655,764,686주이며, 이 중 보통주
B14: 2,000,000주를 감자하고 상환전환우선주(RCPS) 299,330주가 보통주로
B15: 전환되었으며, 상환전환 우선주 (RCPS) 12,904,210주는 전량 소각하여,
B16: 당기말 현재 발행주식의 총수는 640,561,146주(보통주)입니다.
B17: 당기말 현재 유가증권시장에 상장된 주식수는 640,561,146주이며,
B18: 유통주식수는 자기주식 95,978주를 제외한 640,465,168주입니다.
B20: (기준일 : | C20: 45657 | D20: ) | E20: (단위 : 주, %)
B21: 구 분 | D21: 주식의 종류 | G21: 비고
D22: 보통주 | E22: 우선주 | F22: 합계
B23: Ⅰ. 발행할 주식의 총수 | D23: 2000000000 | E23: - | F23: 2000000000 | G23: -
B24: Ⅱ. 현재까지 발행한 주식의 총수 | D24: 642561146 | E24: 13203540 | F24: 655764686 | G24: -
B25: Ⅲ. 현재까지 감소한 주식의 총수 | D25: 2000000 | E25: 13203540 | F25: 15203540 | G25: -
C26: 1. 감자 | D26: 2000000 | E26: - | F26: 2000000 | G26: -
C27: 2. 이익소각 | D27: - | E27: - | F27: - | G27: -
C28: 3. 상환주식의 상환 | D28: - | E28: 12904210 | F28: 12904210 | G28: 자기주식 취득 후 소각
C29: 4. 기타 | D29: - | E29: 299330 | F29: 299330 | G29: 상환전환우선주의 전환
B30: Ⅳ. 발행주식의 총수 (Ⅱ-Ⅲ) | D30: 640561146 | E30: - | F30: 640561146 | G30: -
B31: Ⅴ. 자기주식수 | D31: 95978 | E31: - | F31: 95978 | G31: 분할합병 및 포괄적 주식교환 신주/단주취득
B32: Ⅵ. 유통주식수 (Ⅳ-Ⅴ) | D32: 640465168 | E32: - | F32: 640465168 | G32: -
B33: Ⅶ. 자기주식 보유비율 | D33: - | E33: - | F33: - | G33: -
B34: ※ 최근 5년간 주식 수의 주요 변동내역은 아래와 같습니다. - 2020년 02월 06일자로 보통주 44,102,845주를 유상증자(제3자배정)하였습니다. - 2020년 03월 10일자로 두산건설㈜의 상장폐지에 따른 포괄적 주식 교환을 위하여 보통주 6,891,058주를 신주 발행하였고, 발행과정에서 단수주 취득으로 자사주 5,850주를 취득하였습니다. - 2020년 12월 12일자로 보통주 121,495,330주를 유상증자(일반공모)하였습니다. - 2021년 04월 02일자로 두산퓨얼셀㈜ 현물출자로 보통주 47,843,956주를 유상증자(제3자배정)하였습니다. - 2021년 07월 01일자로 두산인프라코어㈜의 투자사업부문 합병에 따라 보통주 83,399,437주가 신규 발행하였고, 분할합병 발행과정에서 단수주 및 매수청구권 행사로 자사주 81,649주를 취득하였습니다. - 2022년 02월 19일자로 보통주 82,872,900주를 유상증자(구주주배정)하였습니다. - 2021년 07월 01일자로 발행한 신주인수권부사채의 신주인수권증권(2WR) 행사로 2022.06.30일까지 보통주 12,566,852주가 신규 발행되었습니다. - 2022년 07월 01일자로 발행한 신주인수권부사채의 신주인수권증권(2WR) 행사로 보통주 3,014,983주가 신규 발행되었으며, 신주인수권부사채의 신주인수권증권(2WR)의 행사기간이 종료되었습니다. - 2023년 03월 29일자로 제59회, 제60회 전환사채가 전부전환이 되어 보통주 2,253,113주를 신주발행하였습니다.
B39: 2-1. 연결 재무상태표
B40: 연결 재무상태표
B41: 제 63 기 1분기말 2025.03.31 현재
B42: 제 62 기말 2024.12.31 현재
B43: (단위 : 백만원)
C44: 제 63 기 1분기말 | D44: 제 62 기말
B45: 자산
B46: 유동자산 | C46: 10508418 | D46: 10049022
B47: 현금및현금성자산 | C47: 2609660 | D47: 2898298 | G47: 2-2. 연결 손익계산서 | M47: 2-2. 연결 손익계산서
B48: 단기금융상품 | C48: 151970 | D48: 143577 | G48: 연결 손익계산서 | M48: 연결 손익계산서
B49: 단기투자증권 | C49: 0 | D49: 0 | G49: 제 63 기 1분기 2025.01.01 부터 2025.03.31 까지 | M49: 제 62 기 2024.01.01 부터 2024.12.31 까지
...

Sheet 한화시스템
A1: 한화시스템
A2: 45777
G4: (단위: 백만) | I4: *NOTE
B5: 주가 | C5: 유통주식수 | D5: 시가총액 | E5: ibd | F5: ltm ebit | G5: tax rate | I5: 분기보고서 내 주식의 총수 기재하지 않아 직전 사업보고서 사용
B6: 32100 | C6: =D24 -> 186993261 | D6: =B6*C6/10^6 -> 6002483.7 | E6: =SUMIF(A:A,E5,E:E)/10^3 -> 672822.29 | F6: =(H41+N40-J41)/10^6 -> 232034.59 | G6: =IF(F6<=200, 0.99, IF(F6<=20000, 0.209, IF(F6<=300000, 0.231, 0.264))) -> 0.231
B9: 4. 주식의 총수 등
B11: 가. 주식의 총수 현황
B12: (기준일 : | C12: 45657 | D12: ) | E12: (단위 : 주, %)
B13: 구 분 | D13: 주식의 종류 | G13: 비고
D14: 보통주 | E14: 종류주식 | F14: 합계
B15: Ⅰ. 발행할 주식의 총수 | D15: 500000000 | E15: - | F15: 500000000 | G15: -
B16: Ⅱ. 현재까지 발행한 주식의 총수 | D16: 188919389 | E16: - | F16: 188919389 | G16: -
B17: Ⅲ. 현재까지 감소한 주식의 총수 | D17: - | E17: - | F17: - | G17: -
C18: 1. 감자 | D18: - | E18: - | F18: - | G18: -
C19: 2. 이익소각 | D19: - | E19: - | F19: - | G19: -
C20: 3. 상환주식의 상환 | D20: - | E20: - | F20: - | G20: -
C21: 4. 기타 | D21: - | E21: - | F21: - | G21: -
B22: Ⅳ. 발행주식의 총수 (Ⅱ-Ⅲ) | D22: 188919389 | E22: - | F22: 188919389 | G22: -
B23: Ⅴ. 자기주식수 | D23: 1926128 | E23: - | F23: 1926128 | G23: -
B24: Ⅵ. 유통주식수 (Ⅳ-Ⅴ) | D24: 186993261 | E24: - | F24: 186993261 | G24: -
B25: Ⅶ. 자기주식 보유비율 | D25: 1.02 | E25: - | F25: 1.02 | G25: -
B30: 2-1. 연결 재무상태표 | G30: 2-2. 연결 포괄손익계산서 | M30: 연결 포괄손익계산서
B31: 연결 재무상태표 | G31: 연결 포괄손익계산서 | M31: 제 25 기 2024.01.01 부터 2024.12.31 까지
B32: 제 26 기 1분기말 2025.03.31 현재 | G32: 제 26 기 1분기 2025.01.01 부터 2025.03.31 까지 | M32: 제 24 기 2023.01.01 부터 2023.12.31 까지
B33: 제 25 기말 2024.12.31 현재 | G33: 제 25 기 1분기 2024.01.01 부터 2024.03.31 까지 | M33: 제 23 기 2022.01.01 부터 2022.12.31 까지
B34: (단위 : 원) | G34: (단위 : 원) | M34: (단위 : 원)
C35: 제 26 기 1분기말 | D35: 제 25 기말 | H35: 제 26 기 1분기 | J35: 제 25 기 1분기 | N35: 제 25 기 | O35: 제 24 기 | P35: 제 23 기
B36: 자산 | H36: 3개월 | I36: 누적 | J36: 3개월 | K36: 누적 | M36: 매출액 | N36: 2803686058274 | O36: 2452494865652 | P36: 2187382784077
B37: 유동자산 | C37: 2418286851683 | D37: 2286147317733 | G37: 매출액 | H37: 690100705524 | I37: 690100705524 | J37: 544171697458 | K37: 544171697458 | M37: 매출원가 | N37: 2387893541859 | O37: 2148350487679 | P37: 1932111383713
B38: 현금및현금성자산 | C38: 240375736929 | D38: 199842738640 | G38: 매출원가 | H38: 578635666718 | I38: 578635666718 | J38: 458017757393 | K38: 458017757393 | M38: 매출총이익 | N38: 415792516415 | O38: 304144377973 | P38: 255271400364
B39: 매출채권 및 기타유동채권 | C39: 251595804206 | D39: 309758809799 | G39: 매출총이익 | H39: 111465038806 | I39: 111465038806 | J39: 86153940065 | K39: 86153940065 | M39: 판매비와관리비 | N39: 196447218733 | O39: 181569236969 | P39: 192967772698
B40: 기타유동금융자산 | C40: 107170965006 | D40: 124138313927 | G40: 판매비와관리비 | H40: 53300686503 | I40: 53300686503 | J40: 40678878429 | K40: 40678878429 | M40: 영업이익(손실) | N40: 219345297682 | O40: 122575141004 | P40: 62303627666
B41: 기타유동자산 | C41: 1113491159898 | D41: 1025685101781 | G41: 영업이익(손실) | H41: 58164352303 | I41: 58164352303 | J41: 45475061636 | K41: 45475061636 | M41: 기타이익 | N41: 471189148580 | O41: 381777493578 | P41: 8080822090
B42: 유동재고자산 | C42: 705653185644 | D42: 610096270571 | G42: 기타이익 | H42: 39556431954 | I42: 39556431954 | J42: 43736584704 | K42: 43736584704 | M42: 기타손실 | N42: 105181510953 | O42: 44361931795 | P42: 84898552636
B43: 매각예정 또는 소유주에 대한 분배예정으로 분류된 비유동자산이나 처분자산집단 | C43: 0 | D43: 16626083015 | G43: 기타손실 | H43: 62821422844 | I43: 62821422844 | J43: 1166000265 | K43: 1166000265 | M43: 금융수익 | N43: 48063606585 | O43: 31524196161 | P43: 35051390040
B44: 비유동자산 | C44: 4794325951780 | D44: 3437862797985 | G44: 금융수익 | H44: 16395091333 | I44: 16395091333 | J44: 8636267088 | K44: 8636267088 | M44: 금융원가 | N44: 39407264646 | O44: 17408047107 | P44: 11985829095
B45: 비유동당기손익인식금융자산 | C45: 395796314696 | D45: 366532174827 | G45: 금융원가 | H45: 10108289449 | I45: 10108289449 | J45: 5106319360 | K45: 5106319360 | M45: 지분법손익 | N45: -12596342874 | O45: -30247728517 | P45: -26708314516
B46: 기타포괄손익-공정가치 측정 비유동금융자산 | C46: 2770648647001 | D46: 1438036682961 | G46: 지분법손익 | H46: -1914582266 | I46: -1914582266 | J46: -22271994223 | K46: -22271994223 | M46: 법인세비용차감전순이익(손실) | N46: 581412934374 | O46: 443859123324 | P46: -18156856451
B47: 기타비유동금융자산 | C47: 74398385546 | D47: 74055892315 | G47: 법인세비용차감전순이익(손실) | H47: 39271581031 | I47: 39271581031 | J47: 69303599580 | K47: 69303599580 | M47: 법인세비용(수익) | N47: 104258545307 | O47: 57411211791 | P47: 23735116786
B48: 관계기업에 대한 투자자산 | C48: 19301342014 | D48: 24551532882 | G48: 법인세비용(수익) | H48: 5838641620 | I48: 5838641620 | J48: 9122826801 | K48: 9122826801 | M48: 계속영업이익(손실) | N48: 477154389067 | O48: 386447911533 | P48: -41891973237
...

Sheet LIG넥스원
A1: LIG디펜스앤에어로스페이스
A2: 45777
G4: (단위: 백만)
B5: 주가 | C5: 유통주식수 | D5: 시가총액 | E5: ibd | F5: ltm ebit | G5: tax rate
B6: 248000 | C6: =D25 -> 21794360 | D6: =(B6*C6)/10^6 -> 5405001.3 | E6: =SUMIF(A:A,E5,E:E)/10^3 -> 295353.18 | F6: =(H41+N41-J41)/10^6 -> 276386.04 | G6: =IF(F6<=200, 0.99, IF(F6<=20000, 0.209, IF(F6<=300000, 0.231, 0.264))) -> 0.231
B9: 4. 주식의 총수 등
B11: 가. 주식의 총수 현황
B12: 당사의 정관상 발행가능한 주식의 총수는 100,000,000주이며, 발행한 주식의 총수는 보통주 22,000,000주 입니다. 2024년 12월 31일 기준 및 보고서 제출일 현재 당사가 보통주 외에 발행한 주식은 없습니다. | C12: 2024.12.31 | D12: )
B13: (기준일 : | C13: 45747 | D13: ) | E13: (단위 : 주, %) | G13: 비고
B14: 구 분 | D14: 주식의 종류 | G14: 비고
D15: 보통주 | E15: 우선주 | F15: 합계
B16: Ⅰ. 발행할 주식의 총수 | D16: 90000000 | E16: 10000000 | F16: 100000000 | G16: -
B17: Ⅱ. 현재까지 발행한 주식의 총수 | D17: 22000000 | E17: - | F17: 22000000 | G17: -
B18: Ⅲ. 현재까지 감소한 주식의 총수 | D18: - | E18: - | F18: - | G18: -
C19: 1. 감자 | D19: - | E19: - | F19: - | G19: -
C20: 2. 이익소각 | D20: - | E20: - | F20: - | G20: -
C21: 3. 상환주식의 상환 | D21: - | E21: - | F21: - | G21: -
C22: 4. 기타 | D22: - | E22: - | F22: - | G22: -
B23: Ⅳ. 발행주식의 총수 (Ⅱ-Ⅲ) | D23: 22000000 | E23: - | F23: 22000000 | G23: -
B24: Ⅴ. 자기주식수 | D24: 205640 | E24: - | F24: 205640 | G24: -
B25: Ⅵ. 유통주식수 (Ⅳ-Ⅴ) | D25: 21794360 | E25: - | F25: 21794360 | G25: -
B26: Ⅶ. 자기주식 보유비율 | D26: 0.93 | E26: - | F26: 0.93 | G26: -
D27: - | E27: - | F27: - | G27: -
B30: 2-1. 연결 재무상태표 | G30: 2-2. 연결 포괄손익계산서 | M30: 2-2. 연결 포괄손익계산서
B31: 연결 재무상태표 | G31: 연결 포괄손익계산서 | M31: 연결 포괄손익계산서
B32: 제 24 기 1분기말 2025.03.31 현재 | G32: 제 24 기 1분기 2025.01.01 부터 2025.03.31 까지 | M32: 제 23 기 2024.01.01 부터 2024.12.31 까지
B33: 제 23 기말 2024.12.31 현재 | G33: 제 23 기 1분기 2024.01.01 부터 2024.03.31 까지 | M33: 제 22 기 2023.01.01 부터 2023.12.31 까지
B34: (단위 : 원) | G34: (단위 : 원) | M34: 제 21 기 2022.01.01 부터 2022.12.31 까지
C35: 제 24 기 1분기말 | D35: 제 23 기말 | H35: 제 24 기 1분기 | J35: 제 23 기 1분기 | M35: (단위 : 원)
B36: 자산 | H36: 3개월 | I36: 누적 | J36: 3개월 | K36: 누적 | N36: 제 23 기 | O36: 제 22 기 | P36: 제 21 기
B37: 유동자산 | C37: 4364826755192 | D37: 3894568274428 | G37: 수익(매출액) | H37: 907622648219 | I37: 907622648219 | J37: 763536502941 | K37: 763536502941 | M37: 수익(매출액) | N37: 3276339508425 | O37: 2308571092877 | P37: 2220751868438
B38: 현금및현금성자산 | C38: 122982509455 | D38: 546947952484 | G38: 매출원가 | H38: 733980258876 | I38: 733980258876 | J38: 657287629253 | K38: 657287629253 | M38: 매출원가 | N38: 2823712221178 | O38: 1961778919898 | P38: 1894209846592
B39: 매출채권 | C39: 299191431810 | D39: 364450287404 | G39: 매출총이익 | H39: 173642389343 | I39: 173642389343 | J39: 106248873688 | K39: 106248873688 | M39: 매출총이익 | N39: 452627287247 | O39: 346792172979 | P39: 326542021846
B40: 유동계약자산 | C40: 706348728363 | D40: 458999591583 | G40: 판매비와관리비 | H40: 60045463407 | I40: 60045463407 | J40: 39258594314 | K40: 39258594314 | M40: 판매비와관리비 | N40: 222847894976 | O40: 160413734039 | P40: 147430283974
B41: 유동재고자산 | C41: 301998296897 | D41: 363527737579 | G41: 영업이익(손실) | H41: 113596925936 | I41: 113596925936 | J41: 66990279374 | K41: 66990279374 | M41: 영업이익(손실) | N41: 229779392271 | O41: 186378438940 | P41: 179111737872
B42: 기타유동금융자산 | C42: 97493572159 | D42: 82169825799 | G42: 금융수익 | H42: 2487341066 | I42: 2487341066 | J42: 8947541229 | K42: 8947541229 | M42: 금융수익 | N42: 27824271978 | O42: 9578470422 | P42: 34411637673
B43: 기타유동자산 | C43: 2836812207908 | D43: 2078472879579 | G43: 금융원가 | H43: 3499735850 | I43: 3499735850 | J43: 16764956793 | K43: 16764956793 | M43: 금융원가 | N43: 84519397962 | O43: 15281784063 | P43: 36297682943
B44: 당기법인세자산 | C44: 8600 | D44: 0 | G44: 기타이익 | H44: 4126760355 | I44: 4126760355 | J44: 23001008528 | K44: 23001008528 | M44: 기타이익 | N44: 86274860803 | O44: 25590118881 | P44: 49157184720
B45: 비유동자산 | C45: 2253108836826 | D45: 2230696378789 | G45: 기타손실 | H45: 14477634940 | I45: 14477634940 | J45: 13018872641 | K45: 13018872641 | M45: 기타손실 | N45: 49798805244 | O45: 21363906572 | P45: 70782113607
B46: 비유동매출채권 | C46: 8855579171 | D46: 4407734259 | G46: 지분법이익 | H46: 365642462 | I46: 365642462 | J46: 252250388 | K46: 252250388 | M46: 지분법이익 | N46: 68898126 | O46: 101108735 | P46: 2171189980
...
